Workbook

Sheet INSTRUÇÕES
B2: PAINEL EXECUTIVO
B4: EM ABERTO | C4: CRÍTICOS | D4: ATENÇÃO | E4: CONCLUÍDOS | F4: TOTAL
B5: =COUNTIFS(CHAMADOS_GOP!B2:B1000,"<>",CHAMADOS_GOP!O2:O1000,"<>27 - Instalação concluída",CHAMADOS_GOP!O2:O1000,"<>28 - Encerrado") -> 17 | C5: =COUNTIF(CHAMADOS_GOP!Y2:Y1000,"*CRÍTICO*") -> 5 | D5: =COUNTIF(CHAMADOS_GOP!Y2:Y1000,"*ATENÇÃO*") -> 1 | E5: =COUNTIF(CHAMADOS_GOP!O2:O1000,"27 - Instalação concluída") -> 11 | F5: =COUNTIF(CHAMADOS_GOP!B2:B1000,"<>") -> 28
B7: Estado consolidado do conjunto de chamados ativos — atualiza automaticamente
B11: CONTROLE VIVO DE CLIMATIZAÇÃO — GUIA DE USO
B12: GOP / 3ª CRE — SME-RJ | Conforme POP nº 002-25
B14: PROPÓSITO
B15: Centralizar o registro, validação e acompanhamento das demandas de climatização das unidades escolares da 3ª CRE. O arquivo serve à GOP como instrumento de gestão tempestiva, permitindo informar setores parceiros (CTO, CTIN, GIN, CPS, GAD) sobre o estado de cada caso em qualquer momento, sem retrabalho de garimpar e-mails ou planilhas paralelas.
B17: FLUXO DE USO — ORDEM RECOMENDADA
B18: 1) A unidade escolar responde ao Microsoft Forms com a demanda (questões em ROTEIRO_FORMS). 2) A resposta cai automaticamente na aba ENTRADA_UNIDADES. 3) A GOP analisa a entrada e transfere para CHAMADOS_GOP, atribuindo ID, status e responsável. 4) A GOP usa VALIDACAO_GOP para acompanhar o que precisa ser validado tecnicamente. 5) Quando o caso passa para a CTO, ele aparece em VISAO_CTO com prioridade. 6) Cada marco importante é registrado em HISTORICO_RELEVANTE. 7) PAINEL e CONSULTA_UNIDADE são para consulta e prestação de contas.
B20: AS ABAS, UMA A UMA
B21: ROTEIRO_FORMS — questões prontas para criar/atualizar o Microsoft Forms enviado às unidades. ENTRADA_UNIDADES — recebe as respostas brutas do Forms (cópia automática ou manual). CHAMADOS_GOP — base oficial de chamados. Cada linha é uma demanda em andamento. VALIDACAO_GOP — visão filtrada dos chamados que dependem de validação técnica. VISAO_CTO — visão filtrada do que precisa ser tratado pela CTO. PAINEL — indicadores consolidados do conjunto. CONSULTA_UNIDADE — pesquisa rápida por escola, com tudo o que existe sobre ela. HISTORICO_RELEVANTE — linha do tempo dos marcos de cada chamado. CADASTRO_VIVO_3CRE — base cadastral viva das 135 unidades, com inventário e validação. LISTAS — domínios fechados (status, setores, demandas) para validação automática.
B23: REGRAS DE PREENCHIMENTO
B24: • Não digite valores em campos com setinha — use a lista suspensa. Padroniza vocabulário. • IDs de chamado (formato GOP-AR-AAAA-NNNN) são fixos. Não os altere depois de atribuídos. • Datas sempre no formato dd/mm/aaaa. • Sempre que houver movimentação, atualize a coluna DATA ÚLTIMA ATUALIZAÇÃO em CHAMADOS_GOP — ela alimenta o alerta de dias sem movimento. • Em HISTORICO_RELEVANTE, registre apenas marcos (vistoria realizada, orçamento aprovado, aparelho requisitado, instalação concluída). Não registre todo e-mail trocado.
B26: CADASTRO VIVO — COMO MANTER VIVO
... B33: Este arquivo é instrumento de gestão interna da GOP. Não substitui os registros oficiais nos sistemas corporativos da SME nem dispensa o envio dos e-mails formais previstos no POP-002/25. Funciona como camada de controle, memória operacional e prestação de contas do setor.

Sheet PAINEL
A1: CONTROLE VIVO DE CLIMATIZAÇÃO — 3ª CRE/GOP
A2: Fluxo de uso: unidade informa → GOP valida → chamado é acompanhado → CTO recebe visão limpa quando necessário
A3: INDICADOR | B3: Nº | C3: O que significa | E3: ETAPA DO FLUXO (POP) | F3: Qtd | H3: ENVOLVIMENTOS | I3: Qtd
A4: Chamados registrados | B4: =COUNTA(CHAMADOS_GOP!$D$2:$D$1000) -> 28 | C4: Total de chamados cadastrados. | E4: 01 - Recebido da unidade | F4: =COUNTIF(CHAMADOS_GOP!$O$2:$O$1000,E4) -> 0 | H4: GOP | I4: =COUNTIF(CHAMADOS_GOP!$P$2:$P$1000,"*"&H4&"*") -> 11
A5: Chamados abertos | B5: =COUNTIFS(CHAMADOS_GOP!O2:O1000,"<>",CHAMADOS_GOP!O2:O1000,"<>28 - Encerrado") -> 28 | C5: Demandas em acompanhamento. | E5: 02 - Em triagem pela GOP | F5: =COUNTIF(CHAMADOS_GOP!$O$2:$O$1000,E5) -> 1 | H5: CPS | I5: =COUNTIF(CHAMADOS_GOP!$P$2:$P$1000,"*"&H5&"*") -> 2
A6: Pendentes de validação | B6: =COUNTIF(CHAMADOS_GOP!T2:T1000,"Pendente de Vistoria")+COUNTIF(CHAMADOS_GOP!T2:T1000,"Não validada") -> 19 | C6: Casos a conferir pela GOP. | E6: 03 - Vistoria solicitada à CPS | F6: =COUNTIF(CHAMADOS_GOP!$O$2:$O$1000,E6) -> 0 | H6: GIN | I6: =COUNTIF(CHAMADOS_GOP!$P$2:$P$1000,"*"&H6&"*") -> 15
A7: Aguardando CTO | B7: =COUNTIF(CHAMADOS_GOP!P2:P1000,"*CTO*") -> 1 | C7: Chamados sob responsabilidade atual da CTO. | E7: 04 - Aguardando agendamento de vistoria | F7: =COUNTIF(CHAMADOS_GOP!$O$2:$O$1000,E7) -> 1 | H7: GAD | I7: =COUNTIF(CHAMADOS_GOP!$P$2:$P$1000,"*"&H7&"*") -> 0
A8: Parados há mais de 7 dias | B8: =COUNTIFS(CHAMADOS_GOP!S2:S1000,">7",CHAMADOS_GOP!O2:O1000,"<>28 - Encerrado") -> 0 | C8: Demandas para cobrança/revisão. | E8: 05 - Vistoria agendada | F8: =COUNTIF(CHAMADOS_GOP!$O$2:$O$1000,E8) -> 0 | H8: CTO | I8: =COUNTIF(CHAMADOS_GOP!$P$2:$P$1000,"*"&H8&"*") -> 1
A9: Prioridade alta/crítica | B9: =COUNTIFS(CHAMADOS_GOP!Y2:Y1000,"*CRÍTICO*",CHAMADOS_GOP!O2:O1000,"<>28 - Encerrado") -> 5 | C9: Casos preferenciais. | E9: 06 - Aguardando relatório técnico | F9: =COUNTIF(CHAMADOS_GOP!$O$2:$O$1000,E9) -> 0 | H9: CTIN | I9: =COUNTIF(CHAMADOS_GOP!$P$2:$P$1000,"*"&H9&"*") -> 0
E10: 07 - Relatório recebido — unidade apta | F10: =COUNTIF(CHAMADOS_GOP!$O$2:$O$1000,E10) -> 1 | H10: COMP | I10: =COUNTIF(CHAMADOS_GOP!$P$2:$P$1000,"*"&H10&"*") -> 0
E11: 08 - Relatório recebido — unidade não apta | F11: =COUNTIF(CHAMADOS_GOP!$O$2:$O$1000,E11) -> 0 | H11: GMP | I11: =COUNTIF(CHAMADOS_GOP!$P$2:$P$1000,"*"&H11&"*") -> 0
E12: 09 - Aguardando orçamentos da unidade | F12: =COUNTIF(CHAMADOS_GOP!$O$2:$O$1000,E12) -> 7 | H12: Unidade Escolar | I12: =COUNTIF(CHAMADOS_GOP!$P$2:$P$1000,"*"&H12&"*") -> 14
E13: 10 - Orçamentos recebidos | F13: =COUNTIF(CHAMADOS_GOP!$O$2:$O$1000,E13) -> 0
E14: 11 - Orçamentos em análise técnica | F14: =COUNTIF(CHAMADOS_GOP!$O$2:$O$1000,E14) -> 0 | H14: Um chamado pode envolver mais de um setor; a soma pode exceder o total de chamados.
E15: 12 - Orçamento aprovado | F15: =COUNTIF(CHAMADOS_GOP!$O$2:$O$1000,E15) -> 3
E16: 13 - Orçamento reprovado | F16: =COUNTIF(CHAMADOS_GOP!$O$2:$O$1000,E16) -> 0
E17: 14 - Verificando recurso com GAD | F17: =COUNTIF(CHAMADOS_GOP!$O$2:$O$1000,E17) -> 0
E18: 15 - Aguardando remanejamento/nova concessão | F18: =COUNTIF(CHAMADOS_GOP!$O$2:$O$1000,E18) -> 0
E19: 16 - Serviço contratado pela unidade | F19: =COUNTIF(CHAMADOS_GOP!$O$2:$O$1000,E19) -> 0
E20: 17 - Serviço iniciado | F20: =COUNTIF(CHAMADOS_GOP!$O$2:$O$1000,E20) -> 4
E21: 18 - Serviço concluído pela unidade | F21: =COUNTIF(CHAMADOS_GOP!$O$2:$O$1000,E21) -> 0
E22: 19 - Aguardando vistoria de retorno | F22: =COUNTIF(CHAMADOS_GOP!$O$2:$O$1000,E22) -> 0
E23: 20 - Serviço aprovado | F23: =COUNTIF(CHAMADOS_GOP!$O$2:$O$1000,E23) -> 0
E24: 21 - Serviço reprovado — aguardando correção | F24: =COUNTIF(CHAMADOS_GOP!$O$2:$O$1000,E24) -> 0
E25: 22 - Instalação/substituição autorizada | F25: =COUNTIF(CHAMADOS_GOP!$O$2:$O$1000,E25) -> 0
E26: 23 - CTO comunicada | F26: =COUNTIF(CHAMADOS_GOP!$O$2:$O$1000,E26) -> 0
... E32: 29 - Suspenso/pendente de decisão superior | F32: =COUNTIF(CHAMADOS_GOP!$O$2:$O$1000,E32) -> 0
A35: CHAMADOS MAIS ANTIGOS SEM ATUALIZAÇÃO — AÇÃO IMEDIATA
A36: ID Chamado | B36: Unidade Escolar | D36: Status Atual | G36: Setor | I36: Dias s/Atual.
A37: =IFERROR(INDEX(CHAMADOS_GOP!$B$2:$B$500,MATCH(1,CHAMADOS_GOP!$AG$2:$AG$500,0)),"") -> GOP-AR-2026-0002 | B37: =IFERROR(VLOOKUP(A37,CHAMADOS_GOP!$B$2:$D$1000,3,FALSE()),"") -> Escola Municipal Bento Ribeiro | D37: =IFERROR(VLOOKUP(A37,CHAMADOS_GOP!$B$2:$O$1000,14,FALSE()),"") -> 09 - Aguardando orçamentos da unidade | G37: =IFERROR(VLOOKUP(A37,CHAMADOS_GOP!$B$2:$P$1000,15,FALSE()),"") -> Unidade Escolar / GIN | I37: =IFERROR(VLOOKUP(A37,CHAMADOS_GOP!$B$2:$S$1000,18,FALSE()),"") -> 7
A38: =IFERROR(INDEX(CHAMADOS_GOP!$B$2:$B$500,MATCH(2,CHAMADOS_GOP!$AG$2:$AG$500,0)),"") -> GOP-AR-2026-0006 | B38: =IFERROR(VLOOKUP(A38,CHAMADOS_GOP!$B$2:$D$1000,3,FALSE()),"") -> Espaço de Desenvolvimento Infantil Padre Nelson Carlos Del Mônaco | D38: =IFERROR(VLOOKUP(A38,CHAMADOS_GOP!$B$2:$O$1000,14,FALSE()),"") -> 12 - Orçamento aprovado | G38: =IFERROR(VLOOKUP(A38,CHAMADOS_GOP!$B$2:$P$1000,15,FALSE()),"") -> GIN / Unidade Escolar | I38: =IFERROR(VLOOKUP(A38,CHAMADOS_GOP!$B$2:$S$1000,18,FALSE()),"") -> 7
A39: =IFERROR(INDEX(CHAMADOS_GOP!$B$2:$B$500,MATCH(3,CHAMADOS_GOP!$AG$2:$AG$500,0)),"") -> GOP-AR-2026-0007 | B39: =IFERROR(VLOOKUP(A39,CHAMADOS_GOP!$B$2:$D$1000,3,FALSE()),"") -> Espaço de Desenvolvimento Infantil Educandário de Santa Cruz | D39: =IFERROR(VLOOKUP(A39,CHAMADOS_GOP!$B$2:$O$1000,14,FALSE()),"") -> 17 - Serviço iniciado | G39: =IFERROR(VLOOKUP(A39,CHAMADOS_GOP!$B$2:$P$1000,15,FALSE()),"") -> GIN / Unidade Escolar | I39: =IFERROR(VLOOKUP(A39,CHAMADOS_GOP!$B$2:$S$1000,18,FALSE()),"") -> 7
A40: =IFERROR(INDEX(CHAMADOS_GOP!$B$2:$B$500,MATCH(4,CHAMADOS_GOP!$AG$2:$AG$500,0)),"") -> GOP-AR-2026-0009 | B40: =IFERROR(VLOOKUP(A40,CHAMADOS_GOP!$B$2:$D$1000,3,FALSE()),"") -> Escola Municipal José Veríssimo | D40: =IFERROR(VLOOKUP(A40,CHAMADOS_GOP!$B$2:$O$1000,14,FALSE()),"") -> 09 - Aguardando orçamentos da unidade | G40: =IFERROR(VLOOKUP(A40,CHAMADOS_GOP!$B$2:$P$1000,15,FALSE()),"") -> Unidade Escolar / GIN | I40: =IFERROR(VLOOKUP(A40,CHAMADOS_GOP!$B$2:$S$1000,18,FALSE()),"") -> 7
A41: =IFERROR(INDEX(CHAMADOS_GOP!$B$2:$B$500,MATCH(5,CHAMADOS_GOP!$AG$2:$AG$500,0)),"") -> GOP-AR-2026-0010 | B41: =IFERROR(VLOOKUP(A41,CHAMADOS_GOP!$B$2:$D$1000,3,FALSE()),"") -> Escola Municipal Professor Augusto Paulino Filho | D41: =IFERROR(VLOOKUP(A41,CHAMADOS_GOP!$B$2:$O$1000,14,FALSE()),"") -> 12 - Orçamento aprovado | G41: =IFERROR(VLOOKUP(A41,CHAMADOS_GOP!$B$2:$P$1000,15,FALSE()),"") -> GIN / Unidade Escolar | I41: =IFERROR(VLOOKUP(A41,CHAMADOS_GOP!$B$2:$S$1000,18,FALSE()),"") -> 7
A42: =IFERROR(INDEX(CHAMADOS_GOP!$B$2:$B$500,MATCH(6,CHAMADOS_GOP!$AG$2:$AG$500,0)),"") -> GOP-AR-2026-0022 | B42: =IFERROR(VLOOKUP(A42,CHAMADOS_GOP!$B$2:$D$1000,3,FALSE()),"") -> Creche Municipal Tia Andreza | D42: =IFERROR(VLOOKUP(A42,CHAMADOS_GOP!$B$2:$O$1000,14,FALSE()),"") -> 09 - Aguardando orçamentos da unidade | G42: =IFERROR(VLOOKUP(A42,CHAMADOS_GOP!$B$2:$P$1000,15,FALSE()),"") -> Unidade Escolar / GIN | I42: =IFERROR(VLOOKUP(A42,CHAMADOS_GOP!$B$2:$S$1000,18,FALSE()),"") -> 7
A43: =IFERROR(INDEX(CHAMADOS_GOP!$B$2:$B$500,MATCH(7,CHAMADOS_GOP!$AG$2:$AG$500,0)),"") -> GOP-AR-2026-0026 | B43: =IFERROR(VLOOKUP(A43,CHAMADOS_GOP!$B$2:$D$1000,3,FALSE()),"") -> Creche Municipal José de Vieira da Silva | D43: =IFERROR(VLOOKUP(A43,CHAMADOS_GOP!$B$2:$O$1000,14,FALSE()),"") -> 09 - Aguardando orçamentos da unidade | G43: =IFERROR(VLOOKUP(A43,CHAMADOS_GOP!$B$2:$P$1000,15,FALSE()),"") -> Unidade Escolar / GIN | I43: =IFERROR(VLOOKUP(A43,CHAMADOS_GOP!$B$2:$S$1000,18,FALSE()),"") -> 7
A44: =IFERROR(INDEX(CHAMADOS_GOP!$B$2:$B$500,MATCH(8,CHAMADOS_GOP!$AG$2:$AG$500,0)),"") -> GOP-AR-2026-0004 | B44: =IFERROR(VLOOKUP(A44,CHAMADOS_GOP!$B$2:$D$1000,3,FALSE()),"") -> CIEP Procópio Ferreira | D44: =IFERROR(VLOOKUP(A44,CHAMADOS_GOP!$B$2:$O$1000,14,FALSE()),"") -> 17 - Serviço iniciado | G44: =IFERROR(VLOOKUP(A44,CHAMADOS_GOP!$B$2:$P$1000,15,FALSE()),"") -> GIN / Unidade Escolar | I44: =IFERROR(VLOOKUP(A44,CHAMADOS_GOP!$B$2:$S$1000,18,FALSE()),"") -> 4
A45: =IFERROR(INDEX(CHAMADOS_GOP!$B$2:$B$500,MATCH(9,CHAMADOS_GOP!$AG$2:$AG$500,0)),"") -> GOP-AR-2026-0008 | B45: =IFERROR(VLOOKUP(A45,CHAMADOS_GOP!$B$2:$D$1000,3,FALSE()),"") -> Escola Municipal Nereu Sampaio | D45: =IFERROR(VLOOKUP(A45,CHAMADOS_GOP!$B$2:$O$1000,14,FALSE()),"") -> 17 - Serviço iniciado | G45: =IFERROR(VLOOKUP(A45,CHAMADOS_GOP!$B$2:$P$1000,15,FALSE()),"") -> GIN / Unidade Escolar | I45: =IFERROR(VLOOKUP(A45,CHAMADOS_GOP!$B$2:$S$1000,18,FALSE()),"") -> 3
A46: =IFERROR(INDEX(CHAMADOS_GOP!$B$2:$B$500,MATCH(10,CHAMADOS_GOP!$AG$2:$AG$500,0)),"") -> GOP-AR-2026-0012 | B46: =IFERROR(VLOOKUP(A46,CHAMADOS_GOP!$B$2:$D$1000,3,FALSE()),"") -> Escola Municipal Eurico Vilela | D46: =IFERROR(VLOOKUP(A46,CHAMADOS_GOP!$B$2:$O$1000,14,FALSE()),"") -> 17 - Serviço iniciado | G46: =IFERROR(VLOOKUP(A46,CHAMADOS_GOP!$B$2:$P$1000,15,FALSE()),"") -> GIN / Unidade Escolar | I46: =IFERROR(VLOOKUP(A46,CHAMADOS_GOP!$B$2:$S$1000,18,FALSE()),"") -> 3

Sheet CONSULTA_UNIDADE
A1: CONSULTA POR UNIDADE ESCOLAR
A2: Selecione uma escola no campo de pesquisa para ver instantaneamente a ficha técnica, chamados e histórico.
A4: Unidade escolar | B4: Selecione a Unidade... | E4: Designação | F4: =IF(OR($B$4="",$B$4="Selecione a Unidade..."),"",IFERROR(INDEX(CADASTRO_VIVO_3CRE!$B$2:$B$150,MATCH($B$4,CADASTRO_VIVO_3CRE!$E$2:$E$150,0)),"Não localizado"))
A5: Endereço | B5: =IF(OR($B$4="",$B$4="Selecione a Unidade..."),"",IFERROR(INDEX(CADASTRO_VIVO_3CRE!$P$2:$P$150,MATCH($B$4,CADASTRO_VIVO_3CRE!$E$2:$E$150,0)),"Não cadastrado")) | E5: Bairro | F5: =IF(OR($B$4="",$B$4="Selecione a Unidade..."),"",IFERROR(INDEX(CADASTRO_VIVO_3CRE!$Q$2:$Q$150,MATCH($B$4,CADASTRO_VIVO_3CRE!$E$2:$E$150,0)),"Não cadastrado"))
A8: RESUMO DA UNIDADE
A9: Total de chamados | B9: =IF(OR($B$4="",$B$4="Selecione a Unidade..."),"",COUNTIF(CHAMADOS_GOP!$D$2:$D$1000,$B$4)) | C9: Chamados em aberto | D9: =IF(OR($B$4="",$B$4="Selecione a Unidade..."),"",COUNTIFS(CHAMADOS_GOP!$D$2:$D$1000,$B$4,CHAMADOS_GOP!$O$2:$O$1000,"<>28 - Encerrado",CHAMADOS_GOP!$O$2:$O$1000,"<>27 - Instalação concluída")) | E9: Concluídos | F9: =IF(OR($B$4="",$B$4="Selecione a Unidade..."),"",COUNTIFS(CHAMADOS_GOP!$D$2:$D$1000,$B$4,CHAMADOS_GOP!$O$2:$O$1000,"27 - Instalação concluída")+COUNTIFS(CHAMADOS_GOP!$D$2:$D$1000,$B$4,CHAMADOS_GOP!$O$2:$O$1000,"28 - Encerrado")) | G9: Críticos / atenção | H9: =IF(OR($B$4="",$B$4="Selecione a Unidade..."),"",COUNTIFS(CHAMADOS_GOP!$D$2:$D$1000,$B$4,CHAMADOS_GOP!$Y$2:$Y$1000,"*CRÍTICO*")+COUNTIFS(CHAMADOS_GOP!$D$2:$D$1000,$B$4,CHAMADOS_GOP!$Y$2:$Y$1000,"*ATENÇÃO*"))
A11: Última atualização | B11: =IF(OR($B$4="",$B$4="Selecione a Unidade..."),"",IF(COUNTIF(CHAMADOS_GOP!$D$2:$D$500,$B$4)=0,"Sem atualização",SUMPRODUCT(MAX((CHAMADOS_GOP!$D$2:$D$500=$B$4)*(CHAMADOS_GOP!$R$2:$R$500))))) | E11: Setor responsável atual | F11: =IF(OR($B$4="",$B$4="Selecione a Unidade..."),"",IFERROR(INDEX(CHAMADOS_GOP!$P$2:$P$500,MATCH(1,CHAMADOS_GOP!$AE$2:$AE$500,0)),"Sem chamado aberto"))
A14: CHAMADOS DA UNIDADE
A15: ID Chamado | B15: Data Abertura | C15: Tipo de Demanda | D15: Local / Sala | E15: Status | F15: Setor | G15: Próxima Ação | H15: Dias s/ Atualização | I15: Alerta SLA
A16: =IF(OR($B$4="",$B$4="Selecione a Unidade..."),"",IFERROR(INDEX(CHAMADOS_GOP!B$2:B$500,MATCH(1,CHAMADOS_GOP!$AE$2:$AE$500,0)),"")) | B16: =IF(OR($B$4="",$B$4="Selecione a Unidade..."),"",IFERROR(INDEX(CHAMADOS_GOP!W$2:W$500,MATCH(1,CHAMADOS_GOP!$AE$2:$AE$500,0)),"")) | C16: =IF(OR($B$4="",$B$4="Selecione a Unidade..."),"",IFERROR(INDEX(CHAMADOS_GOP!F$2:F$500,MATCH(1,CHAMADOS_GOP!$AE$2:$AE$500,0)),"")) | D16: =IF(OR($B$4="",$B$4="Selecione a Unidade..."),"",IFERROR(INDEX(CHAMADOS_GOP!E$2:E$500,MATCH(1,CHAMADOS_GOP!$AE$2:$AE$500,0)),"")) | E16: =IF(OR($B$4="",$B$4="Selecione a Unidade..."),"",IFERROR(INDEX(CHAMADOS_GOP!O$2:O$500,MATCH(1,CHAMADOS_GOP!$AE$2:$AE$500,0)),"")) | F16: =IF(OR($B$4="",$B$4="Selecione a Unidade..."),"",IFERROR(INDEX(CHAMADOS_GOP!P$2:P$500,MATCH(1,CHAMADOS_GOP!$AE$2:$AE$500,0)),"")) | G16: =IF(OR($B$4="",$B$4="Selecione a Unidade..."),"",IFERROR(INDEX(CHAMADOS_GOP!Q$2:Q$500,MATCH(1,CHAMADOS_GOP!$AE$2:$AE$500,0)),"")) | H16: =IF(OR($B$4="",$B$4="Selecione a Unidade..."),"",IFERROR(INDEX(CHAMADOS_GOP!S$2:S$500,MATCH(1,CHAMADOS_GOP!$AE$2:$AE$500,0)),"")) | I16: =IF(OR($B$4="",$B$4="Selecione a Unidade..."),"",IFERROR(INDEX(CHAMADOS_GOP!Y$2:Y$500,MATCH(1,CHAMADOS_GOP!$AE$2:$AE$500,0)),""))
A17: =IF(OR($B$4="",$B$4="Selecione a Unidade..."),"",IFERROR(INDEX(CHAMADOS_GOP!B$2:B$500,MATCH(2,CHAMADOS_GOP!$AE$2:$AE$500,0)),"")) | B17: =IF(OR($B$4="",$B$4="Selecione a Unidade..."),"",IFERROR(INDEX(CHAMADOS_GOP!W$2:W$500,MATCH(2,CHAMADOS_GOP!$AE$2:$AE$500,0)),"")) | C17: =IF(OR($B$4="",$B$4="Selecione a Unidade..."),"",IFERROR(INDEX(CHAMADOS_GOP!F$2:F$500,MATCH(2,CHAMADOS_GOP!$AE$2:$AE$500,0)),"")) | D17: =IF(OR($B$4="",$B$4="Selecione a Unidade..."),"",IFERROR(INDEX(CHAMADOS_GOP!E$2:E$500,MATCH(2,CHAMADOS_GOP!$AE$2:$AE$500,0)),"")) | E17: =IF(OR($B$4="",$B$4="Selecione a Unidade..."),"",IFERROR(INDEX(CHAMADOS_GOP!O$2:O$500,MATCH(2,CHAMADOS_GOP!$AE$2:$AE$500,0)),"")) | F17: =IF(OR($B$4="",$B$4="Selecione a Unidade..."),"",IFERROR(INDEX(CHAMADOS_GOP!P$2:P$500,MATCH(2,CHAMADOS_GOP!$AE$2:$AE$500,0)),"")) | G17: =IF(OR($B$4="",$B$4="Selecione a Unidade..."),"",IFERROR(INDEX(CHAMADOS_GOP!Q$2:Q$500,MATCH(2,CHAMADOS_GOP!$AE$2:$AE$500,0)),"")) | H17: =IF(OR($B$4="",$B$4="Selecione a Unidade..."),"",IFERROR(INDEX(CHAMADOS_GOP!S$2:S$500,MATCH(2,CHAMADOS_GOP!$AE$2:$AE$500,0)),"")) | I17: =IF(OR($B$4="",$B$4="Selecione a Unidade..."),"",IFERROR(INDEX(CHAMADOS_GOP!Y$2:Y$500,MATCH(2,CHAMADOS_GOP!$AE$2:$AE$500,0)),""))
A18: =IF(OR($B$4="",$B$4="Selecione a Unidade..."),"",IFERROR(INDEX(CHAMADOS_GOP!B$2:B$500,MATCH(3,CHAMADOS_GOP!$AE$2:$AE$500,0)),"")) | B18: =IF(OR($B$4="",$B$4="Selecione a Unidade..."),"",IFERROR(INDEX(CHAMADOS_GOP!W$2:W$500,MATCH(3,CHAMADOS_GOP!$AE$2:$AE$500,0)),"")) | C18: =IF(OR($B$4="",$B$4="Selecione a Unidade..."),"",IFERROR(INDEX(CHAMADOS_GOP!F$2:F$500,MATCH(3,CHAMADOS_GOP!$AE$2:$AE$500,0)),"")) | D18: =IF(OR($B$4="",$B$4="Selecione a Unidade..."),"",IFERROR(INDEX(CHAMADOS_GOP!E$2:E$500,MATCH(3,CHAMADOS_GOP!$AE$2:$AE$500,0)),"")) | E18: =IF(OR($B$4="",$B$4="Selecione a Unidade..."),"",IFERROR(INDEX(CHAMADOS_GOP!O$2:O$500,MATCH(3,CHAMADOS_GOP!$AE$2:$AE$500,0)),"")) | F18: =IF(OR($B$4="",$B$4="Selecione a Unidade..."),"",IFERROR(INDEX(CHAMADOS_GOP!P$2:P$500,MATCH(3,CHAMADOS_GOP!$AE$2:$AE$500,0)),"")) | G18: =IF(OR($B$4="",$B$4="Selecione a Unidade..."),"",IFERROR(INDEX(CHAMADOS_GOP!Q$2:Q$500,MATCH(3,CHAMADOS_GOP!$AE$2:$AE$500,0)),"")) | H18: =IF(OR($B$4="",$B$4="Selecione a Unidade..."),"",IFERROR(INDEX(CHAMADOS_GOP!S$2:S$500,MATCH(3,CHAMADOS_GOP!$AE$2:$AE$500,0)),"")) | I18: =IF(OR($B$4="",$B$4="Selecione a Unidade..."),"",IFERROR(INDEX(CHAMADOS_GOP!Y$2:Y$500,MATCH(3,CHAMADOS_GOP!$AE$2:$AE$500,0)),""))
A19: =IF(OR($B$4="",$B$4="Selecione a Unidade..."),"",IFERROR(INDEX(CHAMADOS_GOP!B$2:B$500,MATCH(4,CHAMADOS_GOP!$AE$2:$AE$500,0)),"")) | B19: =IF(OR($B$4="",$B$4="Selecione a Unidade..."),"",IFERROR(INDEX(CHAMADOS_GOP!W$2:W$500,MATCH(4,CHAMADOS_GOP!$AE$2:$AE$500,0)),"")) | C19: =IF(OR($B$4="",$B$4="Selecione a Unidade..."),"",IFERROR(INDEX(CHAMADOS_GOP!F$2:F$500,MATCH(4,CHAMADOS_GOP!$AE$2:$AE$500,0)),"")) | D19: =IF(OR($B$4="",$B$4="Selecione a Unidade..."),"",IFERROR(INDEX(CHAMADOS_GOP!E$2:E$500,MATCH(4,CHAMADOS_GOP!$AE$2:$AE$500,0)),"")) | E19: =IF(OR($B$4="",$B$4="Selecione a Unidade..."),"",IFERROR(INDEX(CHAMADOS_GOP!O$2:O$500,MATCH(4,CHAMADOS_GOP!$AE$2:$AE$500,0)),"")) | F19: =IF(OR($B$4="",$B$4="Selecione a Unidade..."),"",IFERROR(INDEX(CHAMADOS_GOP!P$2:P$500,MATCH(4,CHAMADOS_GOP!$AE$2:$AE$500,0)),"")) | G19: =IF(OR($B$4="",$B$4="Selecione a Unidade..."),"",IFERROR(INDEX(CHAMADOS_GOP!Q$2:Q$500,MATCH(4,CHAMADOS_GOP!$AE$2:$AE$500,0)),"")) | H19: =IF(OR($B$4="",$B$4="Selecione a Unidade..."),"",IFERROR(INDEX(CHAMADOS_GOP!S$2:S$500,MATCH(4,CHAMADOS_GOP!$AE$2:$AE$500,0)),"")) | I19: =IF(OR($B$4="",$B$4="Selecione a Unidade..."),"",IFERROR(INDEX(CHAMADOS_GOP!Y$2:Y$500,MATCH(4,CHAMADOS_GOP!$AE$2:$AE$500,0)),""))
A20: =IF(OR($B$4="",$B$4="Selecione a Unidade..."),"",IFERROR(INDEX(CHAMADOS_GOP!B$2:B$500,MATCH(5,CHAMADOS_GOP!$AE$2:$AE$500,0)),"")) | B20: =IF(OR($B$4="",$B$4="Selecione a Unidade..."),"",IFERROR(INDEX(CHAMADOS_GOP!W$2:W$500,MATCH(5,CHAMADOS_GOP!$AE$2:$AE$500,0)),"")) | C20: =IF(OR($B$4="",$B$4="Selecione a Unidade..."),"",IFERROR(INDEX(CHAMADOS_GOP!F$2:F$500,MATCH(5,CHAMADOS_GOP!$AE$2:$AE$500,0)),"")) | D20: =IF(OR($B$4="",$B$4="Selecione a Unidade..."),"",IFERROR(INDEX(CHAMADOS_GOP!E$2:E$500,MATCH(5,CHAMADOS_GOP!$AE$2:$AE$500,0)),"")) | E20: =IF(OR($B$4="",$B$4="Selecione a Unidade..."),"",IFERROR(INDEX(CHAMADOS_GOP!O$2:O$500,MATCH(5,CHAMADOS_GOP!$AE$2:$AE$500,0)),"")) | F20: =IF(OR($B$4="",$B$4="Selecione a Unidade..."),"",IFERROR(INDEX(CHAMADOS_GOP!P$2:P$500,MATCH(5,CHAMADOS_GOP!$AE$2:$AE$500,0)),"")) | G20: =IF(OR($B$4="",$B$4="Selecione a Unidade..."),"",IFERROR(INDEX(CHAMADOS_GOP!Q$2:Q$500,MATCH(5,CHAMADOS_GOP!$AE$2:$AE$500,0)),"")) | H20: =IF(OR($B$4="",$B$4="Selecione a Unidade..."),"",IFERROR(INDEX(CHAMADOS_GOP!S$2:S$500,MATCH(5,CHAMADOS_GOP!$AE$2:$AE$500,0)),"")) | I20: =IF(OR($B$4="",$B$4="Selecione a Unidade..."),"",IFERROR(INDEX(CHAMADOS_GOP!Y$2:Y$500,MATCH(5,CHAMADOS_GOP!$AE$2:$AE$500,0)),""))
A21: =IF(OR($B$4="",$B$4="Selecione a Unidade..."),"",IFERROR(INDEX(CHAMADOS_GOP!B$2:B$500,MATCH(6,CHAMADOS_GOP!$AE$2:$AE$500,0)),"")) | B21: =IF(OR($B$4="",$B$4="Selecione a Unidade..."),"",IFERROR(INDEX(CHAMADOS_GOP!W$2:W$500,MATCH(6,CHAMADOS_GOP!$AE$2:$AE$500,0)),"")) | C21: =IF(OR($B$4="",$B$4="Selecione a Unidade..."),"",IFERROR(INDEX(CHAMADOS_GOP!F$2:F$500,MATCH(6,CHAMADOS_GOP!$AE$2:$AE$500,0)),"")) | D21: =IF(OR($B$4="",$B$4="Selecione a Unidade..."),"",IFERROR(INDEX(CHAMADOS_GOP!E$2:E$500,MATCH(6,CHAMADOS_GOP!$AE$2:$AE$500,0)),"")) | E21: =IF(OR($B$4="",$B$4="Selecione a Unidade..."),"",IFERROR(INDEX(CHAMADOS_GOP!O$2:O$500,MATCH(6,CHAMADOS_GOP!$AE$2:$AE$500,0)),"")) | F21: =IF(OR($B$4="",$B$4="Selecione a Unidade..."),"",IFERROR(INDEX(CHAMADOS_GOP!P$2:P$500,MATCH(6,CHAMADOS_GOP!$AE$2:$AE$500,0)),"")) | G21: =IF(OR($B$4="",$B$4="Selecione a Unidade..."),"",IFERROR(INDEX(CHAMADOS_GOP!Q$2:Q$500,MATCH(6,CHAMADOS_GOP!$AE$2:$AE$500,0)),"")) | H21: =IF(OR($B$4="",$B$4="Selecione a Unidade..."),"",IFERROR(INDEX(CHAMADOS_GOP!S$2:S$500,MATCH(6,CHAMADOS_GOP!$AE$2:$AE$500,0)),"")) | I21: =IF(OR($B$4="",$B$4="Selecione a Unidade..."),"",IFERROR(INDEX(CHAMADOS_GOP!Y$2:Y$500,MATCH(6,CHAMADOS_GOP!$AE$2:$AE$500,0)),""))
A22: =IF(OR($B$4="",$B$4="Selecione a Unidade..."),"",IFERROR(INDEX(CHAMADOS_GOP!B$2:B$500,MATCH(7,CHAMADOS_GOP!$AE$2:$AE$500,0)),"")) | B22: =IF(OR($B$4="",$B$4="Selecione a Unidade..."),"",IFERROR(INDEX(CHAMADOS_GOP!W$2:W$500,MATCH(7,CHAMADOS_GOP!$AE$2:$AE$500,0)),"")) | C22: =IF(OR($B$4="",$B$4="Selecione a Unidade..."),"",IFERROR(INDEX(CHAMADOS_GOP!F$2:F$500,MATCH(7,CHAMADOS_GOP!$AE$2:$AE$500,0)),"")) | D22: =IF(OR($B$4="",$B$4="Selecione a Unidade..."),"",IFERROR(INDEX(CHAMADOS_GOP!E$2:E$500,MATCH(7,CHAMADOS_GOP!$AE$2:$AE$500,0)),"")) | E22: =IF(OR($B$4="",$B$4="Selecione a Unidade..."),"",IFERROR(INDEX(CHAMADOS_GOP!O$2:O$500,MATCH(7,CHAMADOS_GOP!$AE$2:$AE$500,0)),"")) | F22: =IF(OR($B$4="",$B$4="Selecione a Unidade..."),"",IFERROR(INDEX(CHAMADOS_GOP!P$2:P$500,MATCH(7,CHAMADOS_GOP!$AE$2:$AE$500,0)),"")) | G22: =IF(OR($B$4="",$B$4="Selecione a Unidade..."),"",IFERROR(INDEX(CHAMADOS_GOP!Q$2:Q$500,MATCH(7,CHAMADOS_GOP!$AE$2:$AE$500,0)),"")) | H22: =IF(OR($B$4="",$B$4="Selecione a Unidade..."),"",IFERROR(INDEX(CHAMADOS_GOP!S$2:S$500,MATCH(7,CHAMADOS_GOP!$AE$2:$AE$500,0)),"")) | I22: =IF(OR($B$4="",$B$4="Selecione a Unidade..."),"",IFERROR(INDEX(CHAMADOS_GOP!Y$2:Y$500,MATCH(7,CHAMADOS_GOP!$AE$2:$AE$500,0)),""))
A23: =IF(OR($B$4="",$B$4="Selecione a Unidade..."),"",IFERROR(INDEX(CHAMADOS_GOP!B$2:B$500,MATCH(8,CHAMADOS_GOP!$AE$2:$AE$500,0)),"")) | B23: =IF(OR($B$4="",$B$4="Selecione a Unidade..."),"",IFERROR(INDEX(CHAMADOS_GOP!W$2:W$500,MATCH(8,CHAMADOS_GOP!$AE$2:$AE$500,0)),"")) | C23: =IF(OR($B$4="",$B$4="Selecione a Unidade..."),"",IFERROR(INDEX(CHAMADOS_GOP!F$2:F$500,MATCH(8,CHAMADOS_GOP!$AE$2:$AE$500,0)),"")) | D23: =IF(OR($B$4="",$B$4="Selecione a Unidade..."),"",IFERROR(INDEX(CHAMADOS_GOP!E$2:E$500,MATCH(8,CHAMADOS_GOP!$AE$2:$AE$500,0)),"")) | E23: =IF(OR($B$4="",$B$4="Selecione a Unidade..."),"",IFERROR(INDEX(CHAMADOS_GOP!O$2:O$500,MATCH(8,CHAMADOS_GOP!$AE$2:$AE$500,0)),"")) | F23: =IF(OR($B$4="",$B$4="Selecione a Unidade..."),"",IFERROR(INDEX(CHAMADOS_GOP!P$2:P$500,MATCH(8,CHAMADOS_GOP!$AE$2:$AE$500,0)),"")) | G23: =IF(OR($B$4="",$B$4="Selecione a Unidade..."),"",IFERROR(INDEX(CHAMADOS_GOP!Q$2:Q$500,MATCH(8,CHAMADOS_GOP!$AE$2:$AE$500,0)),"")) | H23: =IF(OR($B$4="",$B$4="Selecione a Unidade..."),"",IFERROR(INDEX(CHAMADOS_GOP!S$2:S$500,MATCH(8,CHAMADOS_GOP!$AE$2:$AE$500,0)),"")) | I23: =IF(OR($B$4="",$B$4="Selecione a Unidade..."),"",IFERROR(INDEX(CHAMADOS_GOP!Y$2:Y$500,MATCH(8,CHAMADOS_GOP!$AE$2:$AE$500,0)),""))
A24: =IF(OR($B$4="",$B$4="Selecione a Unidade..."),"",IFERROR(INDEX(CHAMADOS_GOP!B$2:B$500,MATCH(9,CHAMADOS_GOP!$AE$2:$AE$500,0)),"")) | B24: =IF(OR($B$4="",$B$4="Selecione a Unidade..."),"",IFERROR(INDEX(CHAMADOS_GOP!W$2:W$500,MATCH(9,CHAMADOS_GOP!$AE$2:$AE$500,0)),"")) | C24: =IF(OR($B$4="",$B$4="Selecione a Unidade..."),"",IFERROR(INDEX(CHAMADOS_GOP!F$2:F$500,MATCH(9,CHAMADOS_GOP!$AE$2:$AE$500,0)),"")) | D24: =IF(OR($B$4="",$B$4="Selecione a Unidade..."),"",IFERROR(INDEX(CHAMADOS_GOP!E$2:E$500,MATCH(9,CHAMADOS_GOP!$AE$2:$AE$500,0)),"")) | E24: =IF(OR($B$4="",$B$4="Selecione a Unidade..."),"",IFERROR(INDEX(CHAMADOS_GOP!O$2:O$500,MATCH(9,CHAMADOS_GOP!$AE$2:$AE$500,0)),"")) | F24: =IF(OR($B$4="",$B$4="Selecione a Unidade..."),"",IFERROR(INDEX(CHAMADOS_GOP!P$2:P$500,MATCH(9,CHAMADOS_GOP!$AE$2:$AE$500,0)),"")) | G24: =IF(OR($B$4="",$B$4="Selecione a Unidade..."),"",IFERROR(INDEX(CHAMADOS_GOP!Q$2:Q$500,MATCH(9,CHAMADOS_GOP!$AE$2:$AE$500,0)),"")) | H24: =IF(OR($B$4="",$B$4="Selecione a Unidade..."),"",IFERROR(INDEX(CHAMADOS_GOP!S$2:S$500,MATCH(9,CHAMADOS_GOP!$AE$2:$AE$500,0)),"")) | I24: =IF(OR($B$4="",$B$4="Selecione a Unidade..."),"",IFERROR(INDEX(CHAMADOS_GOP!Y$2:Y$500,MATCH(9,CHAMADOS_GOP!$AE$2:$AE$500,0)),""))
A25: =IF(OR($B$4="",$B$4="Selecione a Unidade..."),"",IFERROR(INDEX(CHAMADOS_GOP!B$2:B$500,MATCH(10,CHAMADOS_GOP!$AE$2:$AE$500,0)),"")) | B25: =IF(OR($B$4="",$B$4="Selecione a Unidade..."),"",IFERROR(INDEX(CHAMADOS_GOP!W$2:W$500,MATCH(10,CHAMADOS_GOP!$AE$2:$AE$500,0)),"")) | C25: =IF(OR($B$4="",$B$4="Selecione a Unidade..."),"",IFERROR(INDEX(CHAMADOS_GOP!F$2:F$500,MATCH(10,CHAMADOS_GOP!$AE$2:$AE$500,0)),"")) | D25: =IF(OR($B$4="",$B$4="Selecione a Unidade..."),"",IFERROR(INDEX(CHAMADOS_GOP!E$2:E$500,MATCH(10,CHAMADOS_GOP!$AE$2:$AE$500,0)),"")) | E25: =IF(OR($B$4="",$B$4="Selecione a Unidade..."),"",IFERROR(INDEX(CHAMADOS_GOP!O$2:O$500,MATCH(10,CHAMADOS_GOP!$AE$2:$AE$500,0)),"")) | F25: =IF(OR($B$4="",$B$4="Selecione a Unidade..."),"",IFERROR(INDEX(CHAMADOS_GOP!P$2:P$500,MATCH(10,CHAMADOS_GOP!$AE$2:$AE$500,0)),"")) | G25: =IF(OR($B$4="",$B$4="Selecione a Unidade..."),"",IFERROR(INDEX(CHAMADOS_GOP!Q$2:Q$500,MATCH(10,CHAMADOS_GOP!$AE$2:$AE$500,0)),"")) | H25: =IF(OR($B$4="",$B$4="Selecione a Unidade..."),"",IFERROR(INDEX(CHAMADOS_GOP!S$2:S$500,MATCH(10,CHAMADOS_GOP!$AE$2:$AE$500,0)),"")) | I25: =IF(OR($B$4="",$B$4="Selecione a Unidade..."),"",IFERROR(INDEX(CHAMADOS_GOP!Y$2:Y$500,MATCH(10,CHAMADOS_GOP!$AE$2:$AE$500,0)),""))
A26: =IF(OR($B$4="",$B$4="Selecione a Unidade..."),"",IFERROR(INDEX(CHAMADOS_GOP!B$2:B$500,MATCH(11,CHAMADOS_GOP!$AE$2:$AE$500,0)),"")) | B26: =IF(OR($B$4="",$B$4="Selecione a Unidade..."),"",IFERROR(INDEX(CHAMADOS_GOP!W$2:W$500,MATCH(11,CHAMADOS_GOP!$AE$2:$AE$500,0)),"")) | C26: =IF(OR($B$4="",$B$4="Selecione a Unidade..."),"",IFERROR(INDEX(CHAMADOS_GOP!F$2:F$500,MATCH(11,CHAMADOS_GOP!$AE$2:$AE$500,0)),"")) | D26: =IF(OR($B$4="",$B$4="Selecione a Unidade..."),"",IFERROR(INDEX(CHAMADOS_GOP!E$2:E$500,MATCH(11,CHAMADOS_GOP!$AE$2:$AE$500,0)),"")) | E26: =IF(OR($B$4="",$B$4="Selecione a Unidade..."),"",IFERROR(INDEX(CHAMADOS_GOP!O$2:O$500,MATCH(11,CHAMADOS_GOP!$AE$2:$AE$500,0)),"")) | F26: =IF(OR($B$4="",$B$4="Selecione a Unidade..."),"",IFERROR(INDEX(CHAMADOS_GOP!P$2:P$500,MATCH(11,CHAMADOS_GOP!$AE$2:$AE$500,0)),"")) | G26: =IF(OR($B$4="",$B$4="Selecione a Unidade..."),"",IFERROR(INDEX(CHAMADOS_GOP!Q$2:Q$500,MATCH(11,CHAMADOS_GOP!$AE$2:$AE$500,0)),"")) | H26: =IF(OR($B$4="",$B$4="Selecione a Unidade..."),"",IFERROR(INDEX(CHAMADOS_GOP!S$2:S$500,MATCH(11,CHAMADOS_GOP!$AE$2:$AE$500,0)),"")) | I26: =IF(OR($B$4="",$B$4="Selecione a Unidade..."),"",IFERROR(INDEX(CHAMADOS_GOP!Y$2:Y$500,MATCH(11,CHAMADOS_GOP!$AE$2:$AE$500,0)),""))
A27: =IF(OR($B$4="",$B$4="Selecione a Unidade..."),"",IFERROR(INDEX(CHAMADOS_GOP!B$2:B$500,MATCH(12,CHAMADOS_GOP!$AE$2:$AE$500,0)),"")) | B27: =IF(OR($B$4="",$B$4="Selecione a Unidade..."),"",IFERROR(INDEX(CHAMADOS_GOP!W$2:W$500,MATCH(12,CHAMADOS_GOP!$AE$2:$AE$500,0)),"")) | C27: =IF(OR($B$4="",$B$4="Selecione a Unidade..."),"",IFERROR(INDEX(CHAMADOS_GOP!F$2:F$500,MATCH(12,CHAMADOS_GOP!$AE$2:$AE$500,0)),"")) | D27: =IF(OR($B$4="",$B$4="Selecione a Unidade..."),"",IFERROR(INDEX(CHAMADOS_GOP!E$2:E$500,MATCH(12,CHAMADOS_GOP!$AE$2:$AE$500,0)),"")) | E27: =IF(OR($B$4="",$B$4="Selecione a Unidade..."),"",IFERROR(INDEX(CHAMADOS_GOP!O$2:O$500,MATCH(12,CHAMADOS_GOP!$AE$2:$AE$500,0)),"")) | F27: =IF(OR($B$4="",$B$4="Selecione a Unidade..."),"",IFERROR(INDEX(CHAMADOS_GOP!P$2:P$500,MATCH(12,CHAMADOS_GOP!$AE$2:$AE$500,0)),"")) | G27: =IF(OR($B$4="",$B$4="Selecione a Unidade..."),"",IFERROR(INDEX(CHAMADOS_GOP!Q$2:Q$500,MATCH(12,CHAMADOS_GOP!$AE$2:$AE$500,0)),"")) | H27: =IF(OR($B$4="",$B$4="Selecione a Unidade..."),"",IFERROR(INDEX(CHAMADOS_GOP!S$2:S$500,MATCH(12,CHAMADOS_GOP!$AE$2:$AE$500,0)),"")) | I27: =IF(OR($B$4="",$B$4="Selecione a Unidade..."),"",IFERROR(INDEX(CHAMADOS_GOP!Y$2:Y$500,MATCH(12,CHAMADOS_GOP!$AE$2:$AE$500,0)),""))
A28: =IF(OR($B$4="",$B$4="Selecione a Unidade..."),"",IFERROR(INDEX(CHAMADOS_GOP!B$2:B$500,MATCH(13,CHAMADOS_GOP!$AE$2:$AE$500,0)),"")) | B28: =IF(OR($B$4="",$B$4="Selecione a Unidade..."),"",IFERROR(INDEX(CHAMADOS_GOP!W$2:W$500,MATCH(13,CHAMADOS_GOP!$AE$2:$AE$500,0)),"")) | C28: =IF(OR($B$4="",$B$4="Selecione a Unidade..."),"",IFERROR(INDEX(CHAMADOS_GOP!F$2:F$500,MATCH(13,CHAMADOS_GOP!$AE$2:$AE$500,0)),"")) | D28: =IF(OR($B$4="",$B$4="Selecione a Unidade..."),"",IFERROR(INDEX(CHAMADOS_GOP!E$2:E$500,MATCH(13,CHAMADOS_GOP!$AE$2:$AE$500,0)),"")) | E28: =IF(OR($B$4="",$B$4="Selecione a Unidade..."),"",IFERROR(INDEX(CHAMADOS_GOP!O$2:O$500,MATCH(13,CHAMADOS_GOP!$AE$2:$AE$500,0)),"")) | F28: =IF(OR($B$4="",$B$4="Selecione a Unidade..."),"",IFERROR(INDEX(CHAMADOS_GOP!P$2:P$500,MATCH(13,CHAMADOS_GOP!$AE$2:$AE$500,0)),"")) | G28: =IF(OR($B$4="",$B$4="Selecione a Unidade..."),"",IFERROR(INDEX(CHAMADOS_GOP!Q$2:Q$500,MATCH(13,CHAMADOS_GOP!$AE$2:$AE$500,0)),"")) | H28: =IF(OR($B$4="",$B$4="Selecione a Unidade..."),"",IFERROR(INDEX(CHAMADOS_GOP!S$2:S$500,MATCH(13,CHAMADOS_GOP!$AE$2:$AE$500,0)),"")) | I28: =IF(OR($B$4="",$B$4="Selecione a Unidade..."),"",IFERROR(INDEX(CHAMADOS_GOP!Y$2:Y$500,MATCH(13,CHAMADOS_GOP!$AE$2:$AE$500,0)),""))
A29: =IF(OR($B$4="",$B$4="Selecione a Unidade..."),"",IFERROR(INDEX(CHAMADOS_GOP!B$2:B$500,MATCH(14,CHAMADOS_GOP!$AE$2:$AE$500,0)),"")) | B29: =IF(OR($B$4="",$B$4="Selecione a Unidade..."),"",IFERROR(INDEX(CHAMADOS_GOP!W$2:W$500,MATCH(14,CHAMADOS_GOP!$AE$2:$AE$500,0)),"")) | C29: =IF(OR($B$4="",$B$4="Selecione a Unidade..."),"",IFERROR(INDEX(CHAMADOS_GOP!F$2:F$500,MATCH(14,CHAMADOS_GOP!$AE$2:$AE$500,0)),"")) | D29: =IF(OR($B$4="",$B$4="Selecione a Unidade..."),"",IFERROR(INDEX(CHAMADOS_GOP!E$2:E$500,MATCH(14,CHAMADOS_GOP!$AE$2:$AE$500,0)),"")) | E29: =IF(OR($B$4="",$B$4="Selecione a Unidade..."),"",IFERROR(INDEX(CHAMADOS_GOP!O$2:O$500,MATCH(14,CHAMADOS_GOP!$AE$2:$AE$500,0)),"")) | F29: =IF(OR($B$4="",$B$4="Selecione a Unidade..."),"",IFERROR(INDEX(CHAMADOS_GOP!P$2:P$500,MATCH(14,CHAMADOS_GOP!$AE$2:$AE$500,0)),"")) | G29: =IF(OR($B$4="",$B$4="Selecione a Unidade..."),"",IFERROR(INDEX(CHAMADOS_GOP!Q$2:Q$500,MATCH(14,CHAMADOS_GOP!$AE$2:$AE$500,0)),"")) | H29: =IF(OR($B$4="",$B$4="Selecione a Unidade..."),"",IFERROR(INDEX(CHAMADOS_GOP!S$2:S$500,MATCH(14,CHAMADOS_GOP!$AE$2:$AE$500,0)),"")) | I29: =IF(OR($B$4="",$B$4="Selecione a Unidade..."),"",IFERROR(INDEX(CHAMADOS_GOP!Y$2:Y$500,MATCH(14,CHAMADOS_GOP!$AE$2:$AE$500,0)),""))
A30: =IF(OR($B$4="",$B$4="Selecione a Unidade..."),"",IFERROR(INDEX(CHAMADOS_GOP!B$2:B$500,MATCH(15,CHAMADOS_GOP!$AE$2:$AE$500,0)),"")) | B30: =IF(OR($B$4="",$B$4="Selecione a Unidade..."),"",IFERROR(INDEX(CHAMADOS_GOP!W$2:W$500,MATCH(15,CHAMADOS_GOP!$AE$2:$AE$500,0)),"")) | C30: =IF(OR($B$4="",$B$4="Selecione a Unidade..."),"",IFERROR(INDEX(CHAMADOS_GOP!F$2:F$500,MATCH(15,CHAMADOS_GOP!$AE$2:$AE$500,0)),"")) | D30: =IF(OR($B$4="",$B$4="Selecione a Unidade..."),"",IFERROR(INDEX(CHAMADOS_GOP!E$2:E$500,MATCH(15,CHAMADOS_GOP!$AE$2:$AE$500,0)),"")) | E30: =IF(OR($B$4="",$B$4="Selecione a Unidade..."),"",IFERROR(INDEX(CHAMADOS_GOP!O$2:O$500,MATCH(15,CHAMADOS_GOP!$AE$2:$AE$500,0)),"")) | F30: =IF(OR($B$4="",$B$4="Selecione a Unidade..."),"",IFERROR(INDEX(CHAMADOS_GOP!P$2:P$500,MATCH(15,CHAMADOS_GOP!$AE$2:$AE$500,0)),"")) | G30: =IF(OR($B$4="",$B$4="Selecione a Unidade..."),"",IFERROR(INDEX(CHAMADOS_GOP!Q$2:Q$500,MATCH(15,CHAMADOS_GOP!$AE$2:$AE$500,0)),"")) | H30: =IF(OR($B$4="",$B$4="Selecione a Unidade..."),"",IFERROR(INDEX(CHAMADOS_GOP!S$2:S$500,MATCH(15,CHAMADOS_GOP!$AE$2:$AE$500,0)),"")) | I30: =IF(OR($B$4="",$B$4="Selecione a Unidade..."),"",IFERROR(INDEX(CHAMADOS_GOP!Y$2:Y$500,MATCH(15,CHAMADOS_GOP!$AE$2:$AE$500,0)),""))
A31: =IF(OR($B$4="",$B$4="Selecione a Unidade..."),"",IFERROR(INDEX(CHAMADOS_GOP!B$2:B$500,MATCH(16,CHAMADOS_GOP!$AE$2:$AE$500,0)),"")) | B31: =IF(OR($B$4="",$B$4="Selecione a Unidade..."),"",IFERROR(INDEX(CHAMADOS_GOP!W$2:W$500,MATCH(16,CHAMADOS_GOP!$AE$2:$AE$500,0)),"")) | C31: =IF(OR($B$4="",$B$4="Selecione a Unidade..."),"",IFERROR(INDEX(CHAMADOS_GOP!F$2:F$500,MATCH(16,CHAMADOS_GOP!$AE$2:$AE$500,0)),"")) | D31: =IF(OR($B$4="",$B$4="Selecione a Unidade..."),"",IFERROR(INDEX(CHAMADOS_GOP!E$2:E$500,MATCH(16,CHAMADOS_GOP!$AE$2:$AE$500,0)),"")) | E31: =IF(OR($B$4="",$B$4="Selecione a Unidade..."),"",IFERROR(INDEX(CHAMADOS_GOP!O$2:O$500,MATCH(16,CHAMADOS_GOP!$AE$2:$AE$500,0)),"")) | F31: =IF(OR($B$4="",$B$4="Selecione a Unidade..."),"",IFERROR(INDEX(CHAMADOS_GOP!P$2:P$500,MATCH(16,CHAMADOS_GOP!$AE$2:$AE$500,0)),"")) | G31: =IF(OR($B$4="",$B$4="Selecione a Unidade..."),"",IFERROR(INDEX(CHAMADOS_GOP!Q$2:Q$500,MATCH(16,CHAMADOS_GOP!$AE$2:$AE$500,0)),"")) | H31: =IF(OR($B$4="",$B$4="Selecione a Unidade..."),"",IFERROR(INDEX(CHAMADOS_GOP!S$2:S$500,MATCH(16,CHAMADOS_GOP!$AE$2:$AE$500,0)),"")) | I31: =IF(OR($B$4="",$B$4="Selecione a Unidade..."),"",IFERROR(INDEX(CHAMADOS_GOP!Y$2:Y$500,MATCH(16,CHAMADOS_GOP!$AE$2:$AE$500,0)),""))
A32: =IF(OR($B$4="",$B$4="Selecione a Unidade..."),"",IFERROR(INDEX(CHAMADOS_GOP!B$2:B$500,MATCH(17,CHAMADOS_GOP!$AE$2:$AE$500,0)),"")) | B32: =IF(OR($B$4="",$B$4="Selecione a Unidade..."),"",IFERROR(INDEX(CHAMADOS_GOP!W$2:W$500,MATCH(17,CHAMADOS_GOP!$AE$2:$AE$500,0)),"")) | C32: =IF(OR($B$4="",$B$4="Selecione a Unidade..."),"",IFERROR(INDEX(CHAMADOS_GOP!F$2:F$500,MATCH(17,CHAMADOS_GOP!$AE$2:$AE$500,0)),"")) | D32: =IF(OR($B$4="",$B$4="Selecione a Unidade..."),"",IFERROR(INDEX(CHAMADOS_GOP!E$2:E$500,MATCH(17,CHAMADOS_GOP!$AE$2:$AE$500,0)),"")) | E32: =IF(OR($B$4="",$B$4="Selecione a Unidade..."),"",IFERROR(INDEX(CHAMADOS_GOP!O$2:O$500,MATCH(17,CHAMADOS_GOP!$AE$2:$AE$500,0)),"")) | F32: =IF(OR($B$4="",$B$4="Selecione a Unidade..."),"",IFERROR(INDEX(CHAMADOS_GOP!P$2:P$500,MATCH(17,CHAMADOS_GOP!$AE$2:$AE$500,0)),"")) | G32: =IF(OR($B$4="",$B$4="Selecione a Unidade..."),"",IFERROR(INDEX(CHAMADOS_GOP!Q$2:Q$500,MATCH(17,CHAMADOS_GOP!$AE$2:$AE$500,0)),"")) | H32: =IF(OR($B$4="",$B$4="Selecione a Unidade..."),"",IFERROR(INDEX(CHAMADOS_GOP!S$2:S$500,MATCH(17,CHAMADOS_GOP!$AE$2:$AE$500,0)),"")) | I32: =IF(OR($B$4="",$B$4="Selecione a Unidade..."),"",IFERROR(INDEX(CHAMADOS_GOP!Y$2:Y$500,MATCH(17,CHAMADOS_GOP!$AE$2:$AE$500,0)),""))
A33: =IF(OR($B$4="",$B$4="Selecione a Unidade..."),"",IFERROR(INDEX(CHAMADOS_GOP!B$2:B$500,MATCH(18,CHAMADOS_GOP!$AE$2:$AE$500,0)),"")) | B33: =IF(OR($B$4="",$B$4="Selecione a Unidade..."),"",IFERROR(INDEX(CHAMADOS_GOP!W$2:W$500,MATCH(18,CHAMADOS_GOP!$AE$2:$AE$500,0)),"")) | C33: =IF(OR($B$4="",$B$4="Selecione a Unidade..."),"",IFERROR(INDEX(CHAMADOS_GOP!F$2:F$500,MATCH(18,CHAMADOS_GOP!$AE$2:$AE$500,0)),"")) | D33: =IF(OR($B$4="",$B$4="Selecione a Unidade..."),"",IFERROR(INDEX(CHAMADOS_GOP!E$2:E$500,MATCH(18,CHAMADOS_GOP!$AE$2:$AE$500,0)),"")) | E33: =IF(OR($B$4="",$B$4="Selecione a Unidade..."),"",IFERROR(INDEX(CHAMADOS_GOP!O$2:O$500,MATCH(18,CHAMADOS_GOP!$AE$2:$AE$500,0)),"")) | F33: =IF(OR($B$4="",$B$4="Selecione a Unidade..."),"",IFERROR(INDEX(CHAMADOS_GOP!P$2:P$500,MATCH(18,CHAMADOS_GOP!$AE$2:$AE$500,0)),"")) | G33: =IF(OR($B$4="",$B$4="Selecione a Unidade..."),"",IFERROR(INDEX(CHAMADOS_GOP!Q$2:Q$500,MATCH(18,CHAMADOS_GOP!$AE$2:$AE$500,0)),"")) | H33: =IF(OR($B$4="",$B$4="Selecione a Unidade..."),"",IFERROR(INDEX(CHAMADOS_GOP!S$2:S$500,MATCH(18,CHAMADOS_GOP!$AE$2:$AE$500,0)),"")) | I33: =IF(OR($B$4="",$B$4="Selecione a Unidade..."),"",IFERROR(INDEX(CHAMADOS_GOP!Y$2:Y$500,MATCH(18,CHAMADOS_GOP!$AE$2:$AE$500,0)),""))
A34: HISTÓRICO RELEVANTE DA UNIDADE
A35: ID Evento | B35: Data do Evento | C35: ID Chamado | D35: Designação | E35: Unidade Escolar | F35: Marco Relevante | G35: Setor Responsável | H35: Registrado Por | I35: Observação
A36: =IF(OR($B$4="",$B$4="Selecione a Unidade..."),"",IFERROR(INDEX(HISTORICO_RELEVANTE!A$2:A$500,MATCH(1,HISTORICO_RELEVANTE!$K$2:$K$500,0)),"")) | B36: =IF(OR($B$4="",$B$4="Selecione a Unidade..."),"",IFERROR(INDEX(HISTORICO_RELEVANTE!B$2:B$500,MATCH(1,HISTORICO_RELEVANTE!$K$2:$K$500,0)),"")) | C36: =IF(OR($B$4="",$B$4="Selecione a Unidade..."),"",IFERROR(INDEX(HISTORICO_RELEVANTE!C$2:C$500,MATCH(1,HISTORICO_RELEVANTE!$K$2:$K$500,0)),"")) | D36: =IF(OR($B$4="",$B$4="Selecione a Unidade..."),"",IFERROR(INDEX(HISTORICO_RELEVANTE!D$2:D$500,MATCH(1,HISTORICO_RELEVANTE!$K$2:$K$500,0)),"")) | E36: =IF(OR($B$4="",$B$4="Selecione a Unidade..."),"",IFERROR(INDEX(HISTORICO_RELEVANTE!E$2:E$500,MATCH(1,HISTORICO_RELEVANTE!$K$2:$K$500,0)),"")) | F36: =IF(OR($B$4="",$B$4="Selecione a Unidade..."),"",IFERROR(INDEX(HISTORICO_RELEVANTE!F$2:F$500,MATCH(1,HISTORICO_RELEVANTE!$K$2:$K$500,0)),"")) | G36: =IF(OR($B$4="",$B$4="Selecione a Unidade..."),"",IFERROR(INDEX(HISTORICO_RELEVANTE!G$2:G$500,MATCH(1,HISTORICO_RELEVANTE!$K$2:$K$500,0)),"")) | H36: =IF(OR($B$4="",$B$4="Selecione a Unidade..."),"",IFERROR(INDEX(HISTORICO_RELEVANTE!H$2:H$500,MATCH(1,HISTORICO_RELEVANTE!$K$2:$K$500,0)),"")) | I36: =IF(OR($B$4="",$B$4="Selecione a Unidade..."),"",IFERROR(INDEX(HISTORICO_RELEVANTE!I$2:I$500,MATCH(1,HISTORICO_RELEVANTE!$K$2:$K$500,0)),""))
A37: =IF(OR($B$4="",$B$4="Selecione a Unidade..."),"",IFERROR(INDEX(HISTORICO_RELEVANTE!A$2:A$500,MATCH(2,HISTORICO_RELEVANTE!$K$2:$K$500,0)),"")) | B37: =IF(OR($B$4="",$B$4="Selecione a Unidade..."),"",IFERROR(INDEX(HISTORICO_RELEVANTE!B$2:B$500,MATCH(2,HISTORICO_RELEVANTE!$K$2:$K$500,0)),"")) | C37: =IF(OR($B$4="",$B$4="Selecione a Unidade..."),"",IFERROR(INDEX(HISTORICO_RELEVANTE!C$2:C$500,MATCH(2,HISTORICO_RELEVANTE!$K$2:$K$500,0)),"")) | D37: =IF(OR($B$4="",$B$4="Selecione a Unidade..."),"",IFERROR(INDEX(HISTORICO_RELEVANTE!D$2:D$500,MATCH(2,HISTORICO_RELEVANTE!$K$2:$K$500,0)),"")) | E37: =IF(OR($B$4="",$B$4="Selecione a Unidade..."),"",IFERROR(INDEX(HISTORICO_RELEVANTE!E$2:E$500,MATCH(2,HISTORICO_RELEVANTE!$K$2:$K$500,0)),"")) | F37: =IF(OR($B$4="",$B$4="Selecione a Unidade..."),"",IFERROR(INDEX(HISTORICO_RELEVANTE!F$2:F$500,MATCH(2,HISTORICO_RELEVANTE!$K$2:$K$500,0)),"")) | G37: =IF(OR($B$4="",$B$4="Selecione a Unidade..."),"",IFERROR(INDEX(HISTORICO_RELEVANTE!G$2:G$500,MATCH(2,HISTORICO_RELEVANTE!$K$2:$K$500,0)),"")) | H37: =IF(OR($B$4="",$B$4="Selecione a Unidade..."),"",IFERROR(INDEX(HISTORICO_RELEVANTE!H$2:H$500,MATCH(2,HISTORICO_RELEVANTE!$K$2:$K$500,0)),"")) | I37: =IF(OR($B$4="",$B$4="Selecione a Unidade..."),"",IFERROR(INDEX(HISTORICO_RELEVANTE!I$2:I$500,MATCH(2,HISTORICO_RELEVANTE!$K$2:$K$500,0)),""))
A38: =IF(OR($B$4="",$B$4="Selecione a Unidade..."),"",IFERROR(INDEX(HISTORICO_RELEVANTE!A$2:A$500,MATCH(3,HISTORICO_RELEVANTE!$K$2:$K$500,0)),"")) | B38: =IF(OR($B$4="",$B$4="Selecione a Unidade..."),"",IFERROR(INDEX(HISTORICO_RELEVANTE!B$2:B$500,MATCH(3,HISTORICO_RELEVANTE!$K$2:$K$500,0)),"")) | C38: =IF(OR($B$4="",$B$4="Selecione a Unidade..."),"",IFERROR(INDEX(HISTORICO_RELEVANTE!C$2:C$500,MATCH(3,HISTORICO_RELEVANTE!$K$2:$K$500,0)),"")) | D38: =IF(OR($B$4="",$B$4="Selecione a Unidade..."),"",IFERROR(INDEX(HISTORICO_RELEVANTE!D$2:D$500,MATCH(3,HISTORICO_RELEVANTE!$K$2:$K$500,0)),"")) | E38: =IF(OR($B$4="",$B$4="Selecione a Unidade..."),"",IFERROR(INDEX(HISTORICO_RELEVANTE!E$2:E$500,MATCH(3,HISTORICO_RELEVANTE!$K$2:$K$500,0)),"")) | F38: =IF(OR($B$4="",$B$4="Selecione a Unidade..."),"",IFERROR(INDEX(HISTORICO_RELEVANTE!F$2:F$500,MATCH(3,HISTORICO_RELEVANTE!$K$2:$K$500,0)),"")) | G38: =IF(OR($B$4="",$B$4="Selecione a Unidade..."),"",IFERROR(INDEX(HISTORICO_RELEVANTE!G$2:G$500,MATCH(3,HISTORICO_RELEVANTE!$K$2:$K$500,0)),"")) | H38: =IF(OR($B$4="",$B$4="Selecione a Unidade..."),"",IFERROR(INDEX(HISTORICO_RELEVANTE!H$2:H$500,MATCH(3,HISTORICO_RELEVANTE!$K$2:$K$500,0)),"")) | I38: =IF(OR($B$4="",$B$4="Selecione a Unidade..."),"",IFERROR(INDEX(HISTORICO_RELEVANTE!I$2:I$500,MATCH(3,HISTORICO_RELEVANTE!$K$2:$K$500,0)),""))
A39: =IF(OR($B$4="",$B$4="Selecione a Unidade..."),"",IFERROR(INDEX(HISTORICO_RELEVANTE!A$2:A$500,MATCH(4,HISTORICO_RELEVANTE!$K$2:$K$500,0)),"")) | B39: =IF(OR($B$4="",$B$4="Selecione a Unidade..."),"",IFERROR(INDEX(HISTORICO_RELEVANTE!B$2:B$500,MATCH(4,HISTORICO_RELEVANTE!$K$2:$K$500,0)),"")) | C39: =IF(OR($B$4="",$B$4="Selecione a Unidade..."),"",IFERROR(INDEX(HISTORICO_RELEVANTE!C$2:C$500,MATCH(4,HISTORICO_RELEVANTE!$K$2:$K$500,0)),"")) | D39: =IF(OR($B$4="",$B$4="Selecione a Unidade..."),"",IFERROR(INDEX(HISTORICO_RELEVANTE!D$2:D$500,MATCH(4,HISTORICO_RELEVANTE!$K$2:$K$500,0)),"")) | E39: =IF(OR($B$4="",$B$4="Selecione a Unidade..."),"",IFERROR(INDEX(HISTORICO_RELEVANTE!E$2:E$500,MATCH(4,HISTORICO_RELEVANTE!$K$2:$K$500,0)),"")) | F39: =IF(OR($B$4="",$B$4="Selecione a Unidade..."),"",IFERROR(INDEX(HISTORICO_RELEVANTE!F$2:F$500,MATCH(4,HISTORICO_RELEVANTE!$K$2:$K$500,0)),"")) | G39: =IF(OR($B$4="",$B$4="Selecione a Unidade..."),"",IFERROR(INDEX(HISTORICO_RELEVANTE!G$2:G$500,MATCH(4,HISTORICO_RELEVANTE!$K$2:$K$500,0)),"")) | H39: =IF(OR($B$4="",$B$4="Selecione a Unidade..."),"",IFERROR(INDEX(HISTORICO_RELEVANTE!H$2:H$500,MATCH(4,HISTORICO_RELEVANTE!$K$2:$K$500,0)),"")) | I39: =IF(OR($B$4="",$B$4="Selecione a Unidade..."),"",IFERROR(INDEX(HISTORICO_RELEVANTE!I$2:I$500,MATCH(4,HISTORICO_RELEVANTE!$K$2:$K$500,0)),""))
A40: =IF(OR($B$4="",$B$4="Selecione a Unidade..."),"",IFERROR(INDEX(HISTORICO_RELEVANTE!A$2:A$500,MATCH(5,HISTORICO_RELEVANTE!$K$2:$K$500,0)),"")) | B40: =IF(OR($B$4="",$B$4="Selecione a Unidade..."),"",IFERROR(INDEX(HISTORICO_RELEVANTE!B$2:B$500,MATCH(5,HISTORICO_RELEVANTE!$K$2:$K$500,0)),"")) | C40: =IF(OR($B$4="",$B$4="Selecione a Unidade..."),"",IFERROR(INDEX(HISTORICO_RELEVANTE!C$2:C$500,MATCH(5,HISTORICO_RELEVANTE!$K$2:$K$500,0)),"")) | D40: =IF(OR($B$4="",$B$4="Selecione a Unidade..."),"",IFERROR(INDEX(HISTORICO_RELEVANTE!D$2:D$500,MATCH(5,HISTORICO_RELEVANTE!$K$2:$K$500,0)),"")) | E40: =IF(OR($B$4="",$B$4="Selecione a Unidade..."),"",IFERROR(INDEX(HISTORICO_RELEVANTE!E$2:E$500,MATCH(5,HISTORICO_RELEVANTE!$K$2:$K$500,0)),"")) | F40: =IF(OR($B$4="",$B$4="Selecione a Unidade..."),"",IFERROR(INDEX(HISTORICO_RELEVANTE!F$2:F$500,MATCH(5,HISTORICO_RELEVANTE!$K$2:$K$500,0)),"")) | G40: =IF(OR($B$4="",$B$4="Selecione a Unidade..."),"",IFERROR(INDEX(HISTORICO_RELEVANTE!G$2:G$500,MATCH(5,HISTORICO_RELEVANTE!$K$2:$K$500,0)),"")) | H40: =IF(OR($B$4="",$B$4="Selecione a Unidade..."),"",IFERROR(INDEX(HISTORICO_RELEVANTE!H$2:H$500,MATCH(5,HISTORICO_RELEVANTE!$K$2:$K$500,0)),"")) | I40: =IF(OR($B$4="",$B$4="Selecione a Unidade..."),"",IFERROR(INDEX(HISTORICO_RELEVANTE!I$2:I$500,MATCH(5,HISTORICO_RELEVANTE!$K$2:$K$500,0)),""))
A41: =IF(OR($B$4="",$B$4="Selecione a Unidade..."),"",IFERROR(INDEX(HISTORICO_RELEVANTE!A$2:A$500,MATCH(6,HISTORICO_RELEVANTE!$K$2:$K$500,0)),"")) | B41: =IF(OR($B$4="",$B$4="Selecione a Unidade..."),"",IFERROR(INDEX(HISTORICO_RELEVANTE!B$2:B$500,MATCH(6,HISTORICO_RELEVANTE!$K$2:$K$500,0)),"")) | C41: =IF(OR($B$4="",$B$4="Selecione a Unidade..."),"",IFERROR(INDEX(HISTORICO_RELEVANTE!C$2:C$500,MATCH(6,HISTORICO_RELEVANTE!$K$2:$K$500,0)),"")) | D41: =IF(OR($B$4="",$B$4="Selecione a Unidade..."),"",IFERROR(INDEX(HISTORICO_RELEVANTE!D$2:D$500,MATCH(6,HISTORICO_RELEVANTE!$K$2:$K$500,0)),"")) | E41: =IF(OR($B$4="",$B$4="Selecione a Unidade..."),"",IFERROR(INDEX(HISTORICO_RELEVANTE!E$2:E$500,MATCH(6,HISTORICO_RELEVANTE!$K$2:$K$500,0)),"")) | F41: =IF(OR($B$4="",$B$4="Selecione a Unidade..."),"",IFERROR(INDEX(HISTORICO_RELEVANTE!F$2:F$500,MATCH(6,HISTORICO_RELEVANTE!$K$2:$K$500,0)),"")) | G41: =IF(OR($B$4="",$B$4="Selecione a Unidade..."),"",IFERROR(INDEX(HISTORICO_RELEVANTE!G$2:G$500,MATCH(6,HISTORICO_RELEVANTE!$K$2:$K$500,0)),"")) | H41: =IF(OR($B$4="",$B$4="Selecione a Unidade..."),"",IFERROR(INDEX(HISTORICO_RELEVANTE!H$2:H$500,MATCH(6,HISTORICO_RELEVANTE!$K$2:$K$500,0)),"")) | I41: =IF(OR($B$4="",$B$4="Selecione a Unidade..."),"",IFERROR(INDEX(HISTORICO_RELEVANTE!I$2:I$500,MATCH(6,HISTORICO_RELEVANTE!$K$2:$K$500,0)),""))
A42: =IF(OR($B$4="",$B$4="Selecione a Unidade..."),"",IFERROR(INDEX(HISTORICO_RELEVANTE!A$2:A$500,MATCH(7,HISTORICO_RELEVANTE!$K$2:$K$500,0)),"")) | B42: =IF(OR($B$4="",$B$4="Selecione a Unidade..."),"",IFERROR(INDEX(HISTORICO_RELEVANTE!B$2:B$500,MATCH(7,HISTORICO_RELEVANTE!$K$2:$K$500,0)),"")) | C42: =IF(OR($B$4="",$B$4="Selecione a Unidade..."),"",IFERROR(INDEX(HISTORICO_RELEVANTE!C$2:C$500,MATCH(7,HISTORICO_RELEVANTE!$K$2:$K$500,0)),"")) | D42: =IF(OR($B$4="",$B$4="Selecione a Unidade..."),"",IFERROR(INDEX(HISTORICO_RELEVANTE!D$2:D$500,MATCH(7,HISTORICO_RELEVANTE!$K$2:$K$500,0)),"")) | E42: =IF(OR($B$4="",$B$4="Selecione a Unidade..."),"",IFERROR(INDEX(HISTORICO_RELEVANTE!E$2:E$500,MATCH(7,HISTORICO_RELEVANTE!$K$2:$K$500,0)),"")) | F42: =IF(OR($B$4="",$B$4="Selecione a Unidade..."),"",IFERROR(INDEX(HISTORICO_RELEVANTE!F$2:F$500,MATCH(7,HISTORICO_RELEVANTE!$K$2:$K$500,0)),"")) | G42: =IF(OR($B$4="",$B$4="Selecione a Unidade..."),"",IFERROR(INDEX(HISTORICO_RELEVANTE!G$2:G$500,MATCH(7,HISTORICO_RELEVANTE!$K$2:$K$500,0)),"")) | H42: =IF(OR($B$4="",$B$4="Selecione a Unidade..."),"",IFERROR(INDEX(HISTORICO_RELEVANTE!H$2:H$500,MATCH(7,HISTORICO_RELEVANTE!$K$2:$K$500,0)),"")) | I42: =IF(OR($B$4="",$B$4="Selecione a Unidade..."),"",IFERROR(INDEX(HISTORICO_RELEVANTE!I$2:I$500,MATCH(7,HISTORICO_RELEVANTE!$K$2:$K$500,0)),""))
A43: =IF(OR($B$4="",$B$4="Selecione a Unidade..."),"",IFERROR(INDEX(HISTORICO_RELEVANTE!A$2:A$500,MATCH(8,HISTORICO_RELEVANTE!$K$2:$K$500,0)),"")) | B43: =IF(OR($B$4="",$B$4="Selecione a Unidade..."),"",IFERROR(INDEX(HISTORICO_RELEVANTE!B$2:B$500,MATCH(8,HISTORICO_RELEVANTE!$K$2:$K$500,0)),"")) | C43: =IF(OR($B$4="",$B$4="Selecione a Unidade..."),"",IFERROR(INDEX(HISTORICO_RELEVANTE!C$2:C$500,MATCH(8,HISTORICO_RELEVANTE!$K$2:$K$500,0)),"")) | D43: =IF(OR($B$4="",$B$4="Selecione a Unidade..."),"",IFERROR(INDEX(HISTORICO_RELEVANTE!D$2:D$500,MATCH(8,HISTORICO_RELEVANTE!$K$2:$K$500,0)),"")) | E43: =IF(OR($B$4="",$B$4="Selecione a Unidade..."),"",IFERROR(INDEX(HISTORICO_RELEVANTE!E$2:E$500,MATCH(8,HISTORICO_RELEVANTE!$K$2:$K$500,0)),"")) | F43: =IF(OR($B$4="",$B$4="Selecione a Unidade..."),"",IFERROR(INDEX(HISTORICO_RELEVANTE!F$2:F$500,MATCH(8,HISTORICO_RELEVANTE!$K$2:$K$500,0)),"")) | G43: =IF(OR($B$4="",$B$4="Selecione a Unidade..."),"",IFERROR(INDEX(HISTORICO_RELEVANTE!G$2:G$500,MATCH(8,HISTORICO_RELEVANTE!$K$2:$K$500,0)),"")) | H43: =IF(OR($B$4="",$B$4="Selecione a Unidade..."),"",IFERROR(INDEX(HISTORICO_RELEVANTE!H$2:H$500,MATCH(8,HISTORICO_RELEVANTE!$K$2:$K$500,0)),"")) | I43: =IF(OR($B$4="",$B$4="Selecione a Unidade..."),"",IFERROR(INDEX(HISTORICO_RELEVANTE!I$2:I$500,MATCH(8,HISTORICO_RELEVANTE!$K$2:$K$500,0)),""))
A44: =IF(OR($B$4="",$B$4="Selecione a Unidade..."),"",IFERROR(INDEX(HISTORICO_RELEVANTE!A$2:A$500,MATCH(9,HISTORICO_RELEVANTE!$K$2:$K$500,0)),"")) | B44: =IF(OR($B$4="",$B$4="Selecione a Unidade..."),"",IFERROR(INDEX(HISTORICO_RELEVANTE!B$2:B$500,MATCH(9,HISTORICO_RELEVANTE!$K$2:$K$500,0)),"")) | C44: =IF(OR($B$4="",$B$4="Selecione a Unidade..."),"",IFERROR(INDEX(HISTORICO_RELEVANTE!C$2:C$500,MATCH(9,HISTORICO_RELEVANTE!$K$2:$K$500,0)),"")) | D44: =IF(OR($B$4="",$B$4="Selecione a Unidade..."),"",IFERROR(INDEX(HISTORICO_RELEVANTE!D$2:D$500,MATCH(9,HISTORICO_RELEVANTE!$K$2:$K$500,0)),"")) | E44: =IF(OR($B$4="",$B$4="Selecione a Unidade..."),"",IFERROR(INDEX(HISTORICO_RELEVANTE!E$2:E$500,MATCH(9,HISTORICO_RELEVANTE!$K$2:$K$500,0)),"")) | F44: =IF(OR($B$4="",$B$4="Selecione a Unidade..."),"",IFERROR(INDEX(HISTORICO_RELEVANTE!F$2:F$500,MATCH(9,HISTORICO_RELEVANTE!$K$2:$K$500,0)),"")) | G44: =IF(OR($B$4="",$B$4="Selecione a Unidade..."),"",IFERROR(INDEX(HISTORICO_RELEVANTE!G$2:G$500,MATCH(9,HISTORICO_RELEVANTE!$K$2:$K$500,0)),"")) | H44: =IF(OR($B$4="",$B$4="Selecione a Unidade..."),"",IFERROR(INDEX(HISTORICO_RELEVANTE!H$2:H$500,MATCH(9,HISTORICO_RELEVANTE!$K$2:$K$500,0)),"")) | I44: =IF(OR($B$4="",$B$4="Selecione a Unidade..."),"",IFERROR(INDEX(HISTORICO_RELEVANTE!I$2:I$500,MATCH(9,HISTORICO_RELEVANTE!$K$2:$K$500,0)),""))
A45: =IF(OR($B$4="",$B$4="Selecione a Unidade..."),"",IFERROR(INDEX(HISTORICO_RELEVANTE!A$2:A$500,MATCH(10,HISTORICO_RELEVANTE!$K$2:$K$500,0)),"")) | B45: =IF(OR($B$4="",$B$4="Selecione a Unidade..."),"",IFERROR(INDEX(HISTORICO_RELEVANTE!B$2:B$500,MATCH(10,HISTORICO_RELEVANTE!$K$2:$K$500,0)),"")) | C45: =IF(OR($B$4="",$B$4="Selecione a Unidade..."),"",IFERROR(INDEX(HISTORICO_RELEVANTE!C$2:C$500,MATCH(10,HISTORICO_RELEVANTE!$K$2:$K$500,0)),"")) | D45: =IF(OR($B$4="",$B$4="Selecione a Unidade..."),"",IFERROR(INDEX(HISTORICO_RELEVANTE!D$2:D$500,MATCH(10,HISTORICO_RELEVANTE!$K$2:$K$500,0)),"")) | E45: =IF(OR($B$4="",$B$4="Selecione a Unidade..."),"",IFERROR(INDEX(HISTORICO_RELEVANTE!E$2:E$500,MATCH(10,HISTORICO_RELEVANTE!$K$2:$K$500,0)),"")) | F45: =IF(OR($B$4="",$B$4="Selecione a Unidade..."),"",IFERROR(INDEX(HISTORICO_RELEVANTE!F$2:F$500,MATCH(10,HISTORICO_RELEVANTE!$K$2:$K$500,0)),"")) | G45: =IF(OR($B$4="",$B$4="Selecione a Unidade..."),"",IFERROR(INDEX(HISTORICO_RELEVANTE!G$2:G$500,MATCH(10,HISTORICO_RELEVANTE!$K$2:$K$500,0)),"")) | H45: =IF(OR($B$4="",$B$4="Selecione a Unidade..."),"",IFERROR(INDEX(HISTORICO_RELEVANTE!H$2:H$500,MATCH(10,HISTORICO_RELEVANTE!$K$2:$K$500,0)),"")) | I45: =IF(OR($B$4="",$B$4="Selecione a Unidade..."),"",IFERROR(INDEX(HISTORICO_RELEVANTE!I$2:I$500,MATCH(10,HISTORICO_RELEVANTE!$K$2:$K$500,0)),""))
A46: =IF(OR($B$4="",$B$4="Selecione a Unidade..."),"",IFERROR(INDEX(HISTORICO_RELEVANTE!A$2:A$500,MATCH(11,HISTORICO_RELEVANTE!$K$2:$K$500,0)),"")) | B46: =IF(OR($B$4="",$B$4="Selecione a Unidade..."),"",IFERROR(INDEX(HISTORICO_RELEVANTE!B$2:B$500,MATCH(11,HISTORICO_RELEVANTE!$K$2:$K$500,0)),"")) | C46: =IF(OR($B$4="",$B$4="Selecione a Unidade..."),"",IFERROR(INDEX(HISTORICO_RELEVANTE!C$2:C$500,MATCH(11,HISTORICO_RELEVANTE!$K$2:$K$500,0)),"")) | D46: =IF(OR($B$4="",$B$4="Selecione a Unidade..."),"",IFERROR(INDEX(HISTORICO_RELEVANTE!D$2:D$500,MATCH(11,HISTORICO_RELEVANTE!$K$2:$K$500,0)),"")) | E46: =IF(OR($B$4="",$B$4="Selecione a Unidade..."),"",IFERROR(INDEX(HISTORICO_RELEVANTE!E$2:E$500,MATCH(11,HISTORICO_RELEVANTE!$K$2:$K$500,0)),"")) | F46: =IF(OR($B$4="",$B$4="Selecione a Unidade..."),"",IFERROR(INDEX(HISTORICO_RELEVANTE!F$2:F$500,MATCH(11,HISTORICO_RELEVANTE!$K$2:$K$500,0)),"")) | G46: =IF(OR($B$4="",$B$4="Selecione a Unidade..."),"",IFERROR(INDEX(HISTORICO_RELEVANTE!G$2:G$500,MATCH(11,HISTORICO_RELEVANTE!$K$2:$K$500,0)),"")) | H46: =IF(OR($B$4="",$B$4="Selecione a Unidade..."),"",IFERROR(INDEX(HISTORICO_RELEVANTE!H$2:H$500,MATCH(11,HISTORICO_RELEVANTE!$K$2:$K$500,0)),"")) | I46: =IF(OR($B$4="",$B$4="Selecione a Unidade..."),"",IFERROR(INDEX(HISTORICO_RELEVANTE!I$2:I$500,MATCH(11,HISTORICO_RELEVANTE!$K$2:$K$500,0)),""))
...

Sheet CHAMADOS_GOP
A1: ID RESPOSTA FORMS | B1: ID CHAMADO | C1: DESIGNAÇÃO | D1: UNIDADE ESCOLAR | E1: LOCAL DA DEMANDA | F1: TIPO DE DEMANDA | G1: TIPO DE APARELHO | H1: BTU EXISTENTE | I1: BTU PRETENDIDO | J1: 1º OU 2º APARELHO DO LOCAL | K1: QTD SPLIT SOLICITADO | L1: QTD JANELA SOLICITADO | M1: SALAS SEM CLIMATIZAÇÃO INFORMADAS | N1: RESULTADO/APTIDÃO | O1: STATUS ATUAL | P1: SETOR RESPONSÁVEL ATUAL | Q1: PRÓXIMA PROVIDÊNCIA | R1: DATA ÚLTIMA ATUALIZAÇÃO | S1: DIAS SEM ATUALIZAÇÃO | T1: INFORMAÇÃO VALIDADA? | U1: PRIORIDADE | V1: OBSERVAÇÕES | W1: DATA DE ABERTURA | X1: DIAS EM ABERTO | Y1: ALERTA SLA | Z1: ALERTA ANTIGUIDADE | AB1: ord_val | AC1: ord_ctin | AD1: ord_cto | AE1: ord_cons | AF1: score_antig | AG1: rank_antig
B2: GOP-AR-2026-0001 | C2: =IF(D2="","",IFERROR(INDEX(CADASTRO_VIVO_3CRE!$B$2:$B$150,MATCH(D2,CADASTRO_VIVO_3CRE!$E$2:$E$150,0)),"")) -> 313025 | D2: Escola Municipal Professor Visitação | E2: 6, 8, 9, SR | F2: Substituição/Instalação de Aparelho | G2: Split e janela | K2: 3 | L2: 1 | M2: 0 | N2: Não apta | O2: 12 - Orçamento aprovado | P2: GIN / Unidade Escolar | Q2: Confirmar recurso, data de início e previsão de conclusão das adequações. | R2: 46169 | S2: =IF(R2="","",TODAY()-INT(R2)) -> 2 | T2: Pendente de Vistoria | U2: Média | V2: Status original: CTIN aprovou os orçamentos | Observação original: Aguardando data de início das adequações elétricas | Registro GOP: Previsão de conclusão elétrica 16/06 | W2: 46105 | X2: =IF(W2="","",IF(OR(O2="28 - Encerrado",O2="27 - Instalação concluída"),"Concluído",TODAY()-INT(W2))) -> 66 | Y2: =IF(OR(O2="28 - Encerrado",O2="27 - Instalação concluída"),"OK",IF(AND(B2<>"",S2=""),"ATENÇÃO (Sem data de atualização)",IF(S2="","",IF(S2>30,"CRÍTICO (Sem Atualização >30 dias)",IF(S2>15,"ATENÇÃO (Sem Atualização >15 dias)",IF(X2>90,"CRÍTICO (Aberto >90 dias)","OK")))))) -> OK | Z2: =IF(B2="","",IF(OR(O2="27 - Instalação concluída",O2="28 - Encerrado"),"OK",IF(NOT(ISNUMBER(X2)),"",IF(X2>365,"MUITO ANTIGO (>1 ano)",IF(X2>180,"ANTIGO (>6 meses)",IF(X2>90,"ATENÇÃO ANTIG. (>3 meses)","OK")))))) -> OK | AB2: =IF(AND(B2<>"",OR(T2="Pendente de Vistoria",T2="Não validada")),MAX($AB$1:$AB$1)+1,"") -> 1 | AC2: =IF(AND(B2<>"",OR(ISNUMBER(SEARCH("CTIN",P2)),U2="Alta",O2="07 - Relatório recebido — unidade apta",O2="11 - Orçamentos em análise técnica",O2="22 - Instalação/substituição autorizada")),MAX($AC$1:$AC$1)+1,"") | AD2: =IF(AND(B2<>"",OR(ISNUMBER(SEARCH("CTO",P2)),LEFT(O2,2)="22",LEFT(O2,2)="23",LEFT(O2,2)="24",LEFT(O2,2)="25",LEFT(O2,2)="26",LEFT(O2,2)="27")),MAX($AD$1:$AD$1)+1,"") | AE2: =IF(AND(B2<>"",D2=CONSULTA_UNIDADE!$B$4),MAX($AE$1:$AE$1)+1,"") | AF2: =IF(AND(B2<>"",O2<>"27 - Instalação concluída",O2<>"28 - Encerrado",ISNUMBER(S2)),S2*1000+(1000-ROW()),"") -> 2998 | AG2: =IF(AF2="","",RANK(AF2,$AF$2:$AF$500)) -> 14
B3: GOP-AR-2026-0002 | C3: =IF(D3="","",IFERROR(INDEX(CADASTRO_VIVO_3CRE!$B$2:$B$150,MATCH(D3,CADASTRO_VIVO_3CRE!$E$2:$E$150,0)),"")) -> 313020 | D3: Escola Municipal Bento Ribeiro | E3: A confirmar pela unidade | F3: Substituição/Instalação de Aparelho | M3: 0 | N3: Não apta | O3: 09 - Aguardando orçamentos da unidade | P3: Unidade Escolar / GIN | Q3: Cobrar/receber orçamentos e conferir se contemplam o escopo técnico. | R3: 46164 | S3: =IF(R3="","",TODAY()-INT(R3)) -> 7 | T3: Pendente de Vistoria | U3: Média | V3: Status original: Aguardando novos orçamentos para adequação | Observação original: E/CTIN sinalizou que os orçamentos enviados não atendem - 14/04/2026 | Registro GOP: Visita da CTIN não identificou demanda por aprelhos / Diretor solicita aparel... | W3: 46000 | X3: =IF(W3="","",IF(OR(O3="28 - Encerrado",O3="27 - Instalação concluída"),"Concluído",TODAY()-INT(W3))) -> 171 | Y3: =IF(OR(O3="28 - Encerrado",O3="27 - Instalação concluída"),"OK",IF(AND(B3<>"",S3=""),"ATENÇÃO (Sem data de atualização)",IF(S3="","",IF(S3>30,"CRÍTICO (Sem Atualização >30 dias)",IF(S3>15,"ATENÇÃO (Sem Atualização >15 dias)",IF(X3>90,"CRÍTICO (Aberto >90 dias)","OK")))))) -> CRÍTICO (Aberto >90 dias) | Z3: =IF(B3="","",IF(OR(O3="27 - Instalação concluída",O3="28 - Encerrado"),"OK",IF(NOT(ISNUMBER(X3)),"",IF(X3>365,"MUITO ANTIGO (>1 ano)",IF(X3>180,"ANTIGO (>6 meses)",IF(X3>90,"ATENÇÃO ANTIG. (>3 meses)","OK")))))) -> ATENÇÃO ANTIG. (>3 meses) | AB3: =IF(AND(B3<>"",OR(T3="Pendente de Vistoria",T3="Não validada")),MAX($AB$1:$AB$2)+1,"") -> 2 | AC3: =IF(AND(B3<>"",OR(ISNUMBER(SEARCH("CTIN",P3)),U3="Alta",O3="07 - Relatório recebido — unidade apta",O3="11 - Orçamentos em análise técnica",O3="22 - Instalação/substituição autorizada")),MAX($AC$1:$AC$2)+1,"") | AD3: =IF(AND(B3<>"",OR(ISNUMBER(SEARCH("CTO",P3)),LEFT(O3,2)="22",LEFT(O3,2)="23",LEFT(O3,2)="24",LEFT(O3,2)="25",LEFT(O3,2)="26",LEFT(O3,2)="27")),MAX($AD$1:$AD$2)+1,"") | AE3: =IF(AND(B3<>"",D3=CONSULTA_UNIDADE!$B$4),MAX($AE$1:$AE$2)+1,"") | AF3: =IF(AND(B3<>"",O3<>"27 - Instalação concluída",O3<>"28 - Encerrado",ISNUMBER(S3)),S3*1000+(1000-ROW()),"") -> 7997 | AG3: =IF(AF3="","",RANK(AF3,$AF$2:$AF$500)) -> 1
B4: GOP-AR-2026-0003 | C4: =IF(D4="","",IFERROR(INDEX(CADASTRO_VIVO_3CRE!$B$2:$B$150,MATCH(D4,CADASTRO_VIVO_3CRE!$E$2:$E$150,0)),"")) -> 312805 | D4: Espaço de Desenvolvimento Infantil Tânia Cristina Moreira | E4: Salas: 1, 2, 3, 4, 5, 6, 7 e 8 | F4: Substituição/Instalação de Aparelho | G4: Janela | L4: 8 | N4: Apta | O4: 27 - Instalação concluída | P4: GOP | Q4: Confirmar encerramento e atualizar cadastro vivo da unidade. | R4: 46169 | S4: =IF(R4="","",TODAY()-INT(R4)) -> 2 | T4: Sim | U4: Média | V4: Status original: Serviços elétricos finalizados | Observação original: E/CTIN disse que agendaria vistoria - 20/04/2026 | Registro GOP: Instalados | W4: 45887 | X4: =IF(W4="","",IF(OR(O4="28 - Encerrado",O4="27 - Instalação concluída"),"Concluído",TODAY()-INT(W4))) -> Concluído | Y4: =IF(OR(O4="28 - Encerrado",O4="27 - Instalação concluída"),"OK",IF(AND(B4<>"",S4=""),"ATENÇÃO (Sem data de atualização)",IF(S4="","",IF(S4>30,"CRÍTICO (Sem Atualização >30 dias)",IF(S4>15,"ATENÇÃO (Sem Atualização >15 dias)",IF(X4>90,"CRÍTICO (Aberto >90 dias)","OK")))))) -> OK | Z4: =IF(B4="","",IF(OR(O4="27 - Instalação concluída",O4="28 - Encerrado"),"OK",IF(NOT(ISNUMBER(X4)),"",IF(X4>365,"MUITO ANTIGO (>1 ano)",IF(X4>180,"ANTIGO (>6 meses)",IF(X4>90,"ATENÇÃO ANTIG. (>3 meses)","OK")))))) -> OK | AB4: =IF(AND(B4<>"",OR(T4="Pendente de Vistoria",T4="Não validada")),MAX($AB$1:$AB$3)+1,"") | AC4: =IF(AND(B4<>"",OR(ISNUMBER(SEARCH("CTIN",P4)),U4="Alta",O4="07 - Relatório recebido — unidade apta",O4="11 - Orçamentos em análise técnica",O4="22 - Instalação/substituição autorizada")),MAX($AC$1:$AC$3)+1,"") | AD4: =IF(AND(B4<>"",OR(ISNUMBER(SEARCH("CTO",P4)),LEFT(O4,2)="22",LEFT(O4,2)="23",LEFT(O4,2)="24",LEFT(O4,2)="25",LEFT(O4,2)="26",LEFT(O4,2)="27")),MAX($AD$1:$AD$3)+1,"") -> 1 | AE4: =IF(AND(B4<>"",D4=CONSULTA_UNIDADE!$B$4),MAX($AE$1:$AE$3)+1,"") | AF4: =IF(AND(B4<>"",O4<>"27 - Instalação concluída",O4<>"28 - Encerrado",ISNUMBER(S4)),S4*1000+(1000-ROW()),"") | AG4: =IF(AF4="","",RANK(AF4,$AF$2:$AF$500))
